order-book/a1-a2-testcases/intermediate-front-of-book.in

	# always insert orders to the front of the book, with 20 instruments,
	# using 4 clients and up to 1000 orders per instrument
	
4
o
1 S 0 INSTR2 10000000 294
2 S 1 INSTR2 9999998 311
0 S 2 INSTR2 9999994 358
3 S 3 INSTR2 9999991 272
0 S 4 INSTR2 9999988 359
1 S 5 INSTR2 9999982 344
2 S 6 INSTR2 9999978 91
3 S 7 INSTR2 9999973 348
2 S 8 INSTR2 9999970 174
0 S 9 INSTR2 9999968 249
3 S 10 INSTR2 9999965 112
1 S 11 INSTR2 9999960 193
1 S 12 INSTR2 9999958 187
0 S 13 INSTR2 9999953 311
3 S 14 INSTR2 9999949 371
2 S 15 INSTR2 9999945 237
2 S 16 INSTR2 9999939 96
0 S 17 INSTR2 9999937 151
3 S 18 INSTR2 9999931 79
1 S 19 INSTR2 9999925 376
3 S 20 INSTR2 9999922 216
1 S 21 INSTR2 9999920 251
2 S 22 INSTR2 9999914 221
0 S 23 INSTR2 9999912 218
1 S 24 INSTR2 9999907 368
3 S 25 INSTR2 9999904 176
0 S 26 INSTR2 9999901 119
2 S 27 INSTR2 9999897 74
3 S 28 INSTR2 9999892 87
2 S 29 INSTR2 9999890 316
1 S 30 INSTR2 9999888 159
0 S 31 INSTR2 9999885 355
0 S 32 INSTR2 9999879 390
1 S 33 INSTR2 9999876 178
2 S 34 INSTR2 9999870 360
3 S 35 INSTR2 9999864 167
1 S 36 INSTR2 9999862 77
2 S 37 INSTR2 9999860 225
3 S 38 INSTR2 9999855 194
0 S 39 INSTR2 9999849 357
2 S 40 INSTR2 9999843 342
3 S 41 INSTR2 9999839 415
1 S 42 INSTR2 9999835 333
0 S 43 INSTR2 9999829 163
3 S 44 INSTR2 9999823 416
1 S 45 INSTR2 9999819 129
0 S 46 INSTR2 9999815 228
2 S 47 INSTR2 9999810 282
3 S 48 INSTR2 9999807 255
0 S 49 INSTR2 9999804 395
1 S 50 INSTR2 9999798 346
2 S 51 INSTR2 9999793 143
1 S 52 INSTR2 9999789 235
2 S 53 INSTR2 9999786 258
3 S 54 INSTR2 9999780 276
0 S 55 INSTR2 9999777 178
2 S 56 INSTR2 9999772 296
0 S 57 INSTR2 9999770 235
3 S 58 INSTR2 9999764 228
1 S 59 INSTR2 9999762 125
2 S 60 INSTR2 9999757 224
1 S 61 INSTR2 9999754 222
0 S 62 INSTR2 9999751 372
3 S 63 INSTR2 9999748 134
3 S 64 INSTR2 9999745 326
2 S 65 INSTR2 9999743 321
0 S 66 INSTR2 9999739 75
1 S 67 INSTR2 9999733 300
2 S 68 INSTR2 9999731 114
3 S 69 INSTR2 9999726 244
0 S 70 INSTR2 9999721 358
1 S 71 INSTR2 9999718 87
2 S 72 INSTR2 9999712 297
3 S 73 INSTR2 9999707 184
1 S 74 INSTR2 9999705 369
0 S 75 INSTR2 9999703 331
3 S 76 INSTR2 9999697 83
1 S 77 INSTR2 9999691 98
2 S 78 INSTR2 9999686 72
0 S 79 INSTR2 9999683 109
2 S 80 INSTR2 9999679 323
0 S 81 INSTR2 9999673 94
3 S 82 INSTR2 9999669 260
1 S 83 INSTR2 9999665 195
0 S 84 INSTR2 9999659 352
2 S 85 INSTR2 9999656 384
3 S 86 INSTR2 9999650 136
1 S 87 INSTR2 9999647 329
3 S 88 INSTR2 9999644 332
1 S 89 INSTR2 9999642 282
0 S 90 INSTR2 9999638 351
2 S 91 INSTR2 9999634 72
3 S 92 INSTR2 9999631 129
2 S 93 INSTR2 9999626 419
1 S 94 INSTR2 9999624 340
0 S 95 INSTR2 9999620 240
3 S 96 INSTR2 9999614 279
2 S 97 INSTR2 9999611 96
1 S 98 INSTR2 9999607 412
0 S 99 INSTR2 9999602 239
1 S 100 INSTR2 9999598 158
2 S 101 INSTR2 9999596 274
3 S 102 INSTR2 9999593 267
0 S 103 INSTR2 9999588 319
1 S 104 INSTR2 9999585 314
2 S 105 INSTR2 9999580 404
3 S 106 INSTR2 9999578 94
0 S 107 INSTR2 9999572 85
1 S 108 INSTR2 9999566 308
3 S 109 INSTR2 9999561 182
0 S 110 INSTR2 9999557 392
2 S 111 INSTR2 9999555 239
1 S 112 INSTR2 9999550 344
0 S 113 INSTR2 9999545 305
3 S 114 INSTR2 9999541 178
2 S 115 INSTR2 9999537 332
1 S 116 INSTR2 9999534 260
0 S 117 INSTR2 9999528 353
3 S 118 INSTR2 9999522 299
2 S 119 INSTR2 9999516 97
2 S 120 INSTR2 9999514 125
0 S 121 INSTR2 9999511 224
3 S 122 INSTR2 9999508 255
1 S 123 INSTR2 9999505 81
3 S 124 INSTR2 9999499 332
1 S 125 INSTR2 9999496 148
0 S 126 INSTR2 9999492 348
2 S 127 INSTR2 9999489 330
1 S 128 INSTR2 9999486 96
0 S 129 INSTR2 9999480 349
3 S 130 INSTR2 9999478 88
2 S 131 INSTR2 9999476 365
1 S 132 INSTR2 9999471 111
3 S 133 INSTR2 9999467 377
2 S 134 INSTR2 9999464 357
0 S 135 INSTR2 9999462 399
2 S 136 INSTR2 9999456 117
0 S 137 INSTR2 9999452 255
1 S 138 INSTR2 9999446 115
3 S 139 INSTR2 9999443 76
2 S 140 INSTR2 9999440 145
1 S 141 INSTR2 9999436 236
3 S 142 INSTR2 9999433 226
0 S 143 INSTR2 9999427 303
0 S 144 INSTR2 9999423 249
2 S 145 INSTR2 9999417 90
1 S 146 INSTR2 9999414 404
3 S 147 INSTR2 9999408 311
1 S 148 INSTR2 9999402 419
3 S 149 INSTR2 9999400 390
0 S 150 INSTR2 9999397 192
2 S 151 INSTR2 9999393 400
3 S 152 INSTR2 9999391 146
2 S 153 INSTR2 9999387 178
0 S 154 INSTR2 9999383 110
1 S 155 INSTR2 9999380 136
0 S 156 INSTR2 9999376 258
3 S 157 INSTR2 9999373 228
2 S 158 INSTR2 9999371 395
1 S 159 INSTR2 9999369 78
2 S 160 INSTR2 9999363 120
0 S 161 INSTR2 9999361 319
1 S 162 INSTR2 9999356 221
3 S 163 INSTR2 9999351 168
2 S 164 INSTR2 9999348 75
0 S 165 INSTR2 9999345 375
1 S 166 INSTR2 9999339 247
3 S 167 INSTR2 9999334 75
1 S 168 INSTR2 9999328 71
3 S 169 INSTR2 9999324 202
2 S 170 INSTR2 9999318 267
0 S 171 INSTR2 9999315 174
1 S 172 INSTR2 9999313 358
2 S 173 INSTR2 9999311 78
3 S 174 INSTR2 9999307 419
0 S 175 INSTR2 9999305 242
3 S 176 INSTR2 9999303 219
2 S 177 INSTR2 9999298 86
1 S 178 INSTR2 9999296 154
0 S 179 INSTR2 9999293 285
1 S 180 INSTR2 9999287 96
3 S 181 INSTR2 9999283 95
0 S 182 INSTR2 9999279 122
2 S 183 INSTR2 9999274 419
0 S 184 INSTR2 9999271 114
3 S 185 INSTR2 9999266 167
2 S 186 INSTR2 9999261 124
1 S 187 INSTR2 9999257 301
3 S 188 INSTR2 9999252 304
1 S 189 INSTR2 9999247 414
2 S 190 INSTR2 9999242 108
0 S 191 INSTR2 9999237 296
3 S 192 INSTR2 9999235 271
2 S 193 INSTR2 9999229 238
1 S 194 INSTR2 9999223 301
0 S 195 INSTR2 9999220 360
2 S 196 INSTR2 9999217 121
0 S 197 INSTR2 9999213 354
3 S 198 INSTR2 9999208 364
1 S 199 INSTR2 9999204 284
3 S 200 INSTR2 9999201 190
0 S 201 INSTR2 9999196 318
1 S 202 INSTR2 9999191 332
2 S 203 INSTR2 9999186 103
1 S 204 INSTR2 9999180 366
3 S 205 INSTR2 9999176 346
2 S 206 INSTR2 9999171 351
0 S 207 INSTR2 9999167 251
3 S 208 INSTR2 9999163 284
0 S 209 INSTR2 9999159 328
2 S 210 INSTR2 9999155 414
1 S 211 INSTR2 9999152 159
0 S 212 INSTR2 9999149 261
3 S 213 INSTR2 9999147 247
1 S 214 INSTR2 9999145 200
2 S 215 INSTR2 9999143 265
3 S 216 INSTR2 9999138 399
0 S 217 INSTR2 9999135 280
2 S 218 INSTR2 9999130 405
1 S 219 INSTR2 9999126 145
0 S 220 INSTR2 9999124 298
3 S 221 INSTR2 9999119 355
2 S 222 INSTR2 9999113 265
1 S 223 INSTR2 9999109 295
2 S 224 INSTR2 9999104 192
3 S 225 INSTR2 9999101 110
0 S 226 INSTR2 9999095 390
1 S 227 INSTR2 9999089 310
2 S 228 INSTR2 9999085 328
1 S 229 INSTR2 9999082 139
0 S 230 INSTR2 9999080 223
3 S 231 INSTR2 9999078 202
2 S 232 INSTR2 9999075 138
0 S 233 INSTR2 9999073 410
3 S 234 INSTR2 9999071 70
1 S 235 INSTR2 9999069 118
2 S 236 INSTR2 9999065 275
0 S 237 INSTR2 9999059 209
3 S 238 INSTR2 9999057 339
1 S 239 INSTR2 9999054 251
2 S 240 INSTR2 9999049 254
1 S 241 INSTR2 9999043 143
3 S 242 INSTR2 9999039 268
0 S 243 INSTR2 9999033 417
3 S 244 INSTR2 9999029 236
1 S 245 INSTR2 9999023 269
0 S 246 INSTR2 9999021 123
2 S 247 INSTR2 9999019 199
1 S 248 INSTR2 9999013 302
3 S 249 INSTR2 9999009 147
2 S 250 INSTR2 9999004 371
0 S 251 INSTR2 9998999 365
1 S 252 INSTR2 9998995 147
0 S 253 INSTR2 9998989 141
2 S 254 INSTR2 9998985 175
3 S 255 INSTR2 9998983 103
1 S 256 INSTR2 9998977 183
0 S 257 INSTR2 9998972 172
3 S 258 INSTR2 9998969 264
2 S 259 INSTR2 9998966 289
2 S 260 INSTR2 9998962 273
3 S 261 INSTR2 9998957 204
0 S 262 INSTR2 9998951 404
1 S 263 INSTR2 9998947 166
0 S 264 INSTR2 9998943 162
1 S 265 INSTR2 9998938 405
2 S 266 INSTR2 9998934 90
3 S 267 INSTR2 9998929 289
1 S 268 INSTR2 9998924 231
3 S 269 INSTR2 9998920 81
2 S 270 INSTR2 9998917 183
0 S 271 INSTR2 9998912 416
1 S 272 INSTR2 9998910 226
2 S 273 INSTR2 9998904 169
3 S 274 INSTR2 9998902 192
0 S 275 INSTR2 9998900 376
3 S 276 INSTR2 9998894 372
0 S 277 INSTR2 9998890 214
1 S 278 INSTR2 9998888 331
2 S 279 INSTR2 9998886 147
0 S 280 INSTR2 9998881 411
1 S 281 INSTR2 9998875 332
3 S 282 INSTR2 9998873 152
2 S 283 INSTR2 9998869 200
1 S 284 INSTR2 9998864 210
3 S 285 INSTR2 9998862 204
2 S 286 INSTR2 9998856 363
0 S 287 INSTR2 9998852 146
3 S 288 INSTR2 9998846 236
1 S 289 INSTR2 9998841 278
0 S 290 INSTR2 9998839 97
2 S 291 INSTR2 9998835 306
0 S 292 INSTR2 9998830 218
2 S 293 INSTR2 9998824 348
3 S 294 INSTR2 9998818 160
1 S 295 INSTR2 9998813 92
0 S 296 INSTR2 9998810 380
