order-book/a1-a2-testcases/intermediate-many-matches.in

	# fills up the order book for 10 instruments, then clears it by matching,
	# using 4 clients and up to 5000 orders per instrument
	
4
o
1 S 0 INSTR7 10 380
0 S 1 INSTR7 16 114
2 S 2 INSTR7 21 266
3 S 3 INSTR7 24 208
2 S 4 INSTR7 27 70
1 S 5 INSTR7 32 371
3 S 6 INSTR7 38 124
0 S 7 INSTR7 42 359
1 S 8 INSTR7 45 170
3 S 9 INSTR7 47 225
2 S 10 INSTR7 49 261
0 S 11 INSTR7 54 287
1 S 12 INSTR7 56 229
3 S 13 INSTR7 58 281
0 S 14 INSTR7 62 284
2 S 15 INSTR7 67 105
3 S 16 INSTR7 70 278
1 S 17 INSTR7 73 281
0 S 18 INSTR7 79 296
2 S 19 INSTR7 81 133
1 S 20 INSTR7 86 377
3 S 21 INSTR7 89 77
2 S 22 INSTR7 95 285
0 S 23 INSTR7 99 310
2 S 24 INSTR7 101 192
1 S 25 INSTR7 107 257
3 S 26 INSTR7 109 229
0 S 27 INSTR7 113 301
0 S 28 INSTR7 118 392
3 S 29 INSTR7 123 102
2 S 30 INSTR7 126 399
1 S 31 INSTR7 129 391
2 S 32 INSTR7 135 338
1 S 33 INSTR7 139 160
0 S 34 INSTR7 141 316
3 S 35 INSTR7 146 272
3 S 36 INSTR7 148 156
0 S 37 INSTR7 153 102
2 S 38 INSTR7 158 87
1 S 39 INSTR7 161 400
3 S 40 INSTR7 166 250
1 S 41 INSTR7 172 302
2 S 42 INSTR7 176 144
0 S 43 INSTR7 178 308
0 S 44 INSTR7 182 223
3 S 45 INSTR7 186 319
1 S 46 INSTR7 192 303
2 S 47 INSTR7 196 88
2 S 48 INSTR7 202 109
1 S 49 INSTR7 205 126
0 S 50 INSTR7 210 307
3 S 51 INSTR7 212 293
2 S 52 INSTR7 217 389
0 S 53 INSTR7 222 205
3 S 54 INSTR7 225 357
1 S 55 INSTR7 230 401
3 S 56 INSTR7 234 350
0 S 57 INSTR7 237 105
2 S 58 INSTR7 239 70
1 S 59 INSTR7 243 107
3 S 60 INSTR7 248 73
2 S 61 INSTR7 252 159
0 S 62 INSTR7 256 244
1 S 63 INSTR7 259 227
0 S 64 INSTR7 263 80
2 S 65 INSTR7 269 308
1 S 66 INSTR7 273 94
3 S 67 INSTR7 275 399
2 S 68 INSTR7 278 253
0 S 69 INSTR7 283 383
3 S 70 INSTR7 289 87
1 S 71 INSTR7 293 159
3 S 72 INSTR7 297 107
0 S 73 INSTR7 302 291
1 S 74 INSTR7 306 307
2 S 75 INSTR7 310 364
3 S 76 INSTR7 312 208
2 S 77 INSTR7 315 131
0 S 78 INSTR7 317 78
1 S 79 INSTR7 322 313
3 S 80 INSTR7 324 171
0 S 81 INSTR7 329 310
2 S 82 INSTR7 331 127
1 S 83 INSTR7 335 351
0 S 84 INSTR7 339 269
2 S 85 INSTR7 342 333
3 S 86 INSTR7 346 215
1 S 87 INSTR7 352 159
2 S 88 INSTR7 355 159
3 S 89 INSTR7 359 97
1 S 90 INSTR7 364 171
0 S 91 INSTR7 366 137
3 S 92 INSTR7 370 325
2 S 93 INSTR7 376 252
0 S 94 INSTR7 381 110
1 S 95 INSTR7 385 304
1 S 96 INSTR7 390 254
0 S 97 INSTR7 393 403
3 S 98 INSTR7 399 273
2 S 99 INSTR7 402 378
2 S 100 INSTR7 406 244
1 S 101 INSTR7 411 192
0 S 102 INSTR7 415 348
3 S 103 INSTR7 418 212
0 S 104 INSTR7 424 357
2 S 105 INSTR7 427 359
3 S 106 INSTR7 433 295
1 S 107 INSTR7 437 163
2 S 108 INSTR7 441 85
1 S 109 INSTR7 446 349
3 S 110 INSTR7 450 415
0 S 111 INSTR7 455 279
1 S 112 INSTR7 457 375
3 S 113 INSTR7 461 225
2 S 114 INSTR7 466 179
0 S 115 INSTR7 470 302
0 S 116 INSTR7 472 270
3 S 117 INSTR7 477 199
1 S 118 INSTR7 481 151
2 S 119 INSTR7 486 103
1 S 120 INSTR7 489 351
2 S 121 INSTR7 491 86
0 S 122 INSTR7 495 111
3 S 123 INSTR7 500 310
0 S 124 INSTR7 502 263
3 S 125 INSTR7 508 159
2 S 126 INSTR7 510 205
1 S 127 INSTR7 513 293
0 S 128 INSTR7 519 401
1 S 129 INSTR7 524 144
3 S 130 INSTR7 527 308
2 S 131 INSTR7 532 357
2 S 132 INSTR7 534 200
3 S 133 INSTR7 540 381
1 S 134 INSTR7 545 300
0 S 135 INSTR7 551 86
1 S 136 INSTR7 553 145
2 S 137 INSTR7 555 69
3 S 138 INSTR7 560 276
0 S 139 INSTR7 564 346
2 S 140 INSTR7 570 89
1 S 141 INSTR7 576 280
3 S 142 INSTR7 581 123
0 S 143 INSTR7 585 318
2 S 144 INSTR7 588 392
3 S 145 INSTR7 590 343
1 S 146 INSTR7 595 91
0 S 147 INSTR7 600 393
1 S 148 INSTR7 604 171
3 S 149 INSTR7 608 225
2 S 150 INSTR7 613 357
0 S 151 INSTR7 619 396
0 S 152 INSTR7 624 106
2 S 153 INSTR7 630 319
3 S 154 INSTR7 632 155
1 S 155 INSTR7 636 404
0 S 156 INSTR7 641 182
1 S 157 INSTR7 647 133
3 S 158 INSTR7 651 159
2 S 159 INSTR7 656 246
3 S 160 INSTR7 662 331
0 S 161 INSTR7 665 419
2 S 162 INSTR7 671 320
1 S 163 INSTR7 677 111
2 S 164 INSTR7 682 396
3 S 165 INSTR7 685 151
0 S 166 INSTR7 691 280
1 S 167 INSTR7 693 157
0 S 168 INSTR7 699 388
1 S 169 INSTR7 703 292
3 S 170 INSTR7 709 96
2 S 171 INSTR7 712 398
3 S 172 INSTR7 718 161
2 S 173 INSTR7 723 390
1 S 174 INSTR7 727 126
0 S 175 INSTR7 729 78
3 S 176 INSTR7 734 392
1 S 177 INSTR7 740 107
2 S 178 INSTR7 746 351
0 S 179 INSTR7 751 107
0 S 180 INSTR7 755 275
1 S 181 INSTR7 758 107
3 S 182 INSTR7 764 339
2 S 183 INSTR7 767 197
3 S 184 INSTR7 771 353
2 S 185 INSTR7 775 405
1 S 186 INSTR7 779 374
0 S 187 INSTR7 784 147
2 S 188 INSTR7 786 152
3 S 189 INSTR7 791 139
1 S 190 INSTR7 793 363
0 S 191 INSTR7 796 85
1 S 192 INSTR7 799 207
2 S 193 INSTR7 804 113
3 S 194 INSTR7 806 385
0 S 195 INSTR7 811 84
2 S 196 INSTR7 816 259
0 S 197 INSTR7 819 138
3 S 198 INSTR7 823 387
1 S 199 INSTR7 826 243
1 S 200 INSTR7 830 345
3 S 201 INSTR7 833 340
2 S 202 INSTR7 838 237
0 S 203 INSTR7 840 267
0 S 204 INSTR7 845 171
3 S 205 INSTR7 850 274
1 S 206 INSTR7 853 302
2 S 207 INSTR7 855 88
3 S 208 INSTR7 859 354
1 S 209 INSTR7 864 269
2 S 210 INSTR7 869 241
0 S 211 INSTR7 872 405
1 S 212 INSTR7 876 352
2 S 213 INSTR7 882 296
3 S 214 INSTR7 885 303
0 S 215 INSTR7 890 155
1 S 216 INSTR7 892 197
0 S 217 INSTR7 896 229
3 S 218 INSTR7 899 237
2 S 219 INSTR7 903 382
2 S 220 INSTR7 908 318
0 S 221 INSTR7 913 142
3 S 222 INSTR7 919 411
1 S 223 INSTR7 923 413
1 S 224 INSTR7 929 136
3 S 225 INSTR7 931 340
0 S 226 INSTR7 937 291
2 S 227 INSTR7 943 312
1 S 228 INSTR7 949 163
2 S 229 INSTR7 953 345
3 S 230 INSTR7 958 227
0 S 231 INSTR7 962 119
0 S 232 INSTR7 966 209
3 S 233 INSTR7 969 309
1 S 234 INSTR7 975 130
2 S 235 INSTR7 981 298
0 S 236 INSTR7 984 104
2 S 237 INSTR7 988 176
1 S 238 INSTR7 994 215
3 S 239 INSTR7 1000 72
1 S 240 INSTR7 1004 111
3 S 241 INSTR7 1007 199
0 S 242 INSTR7 1012 309
2 S 243 INSTR7 1015 419
1 S 244 INSTR7 1019 205
0 S 245 INSTR7 1022 323
2 S 246 INSTR7 1027 331
3 S 247 INSTR7 1032 410
3 S 248 INSTR7 1036 86
2 S 249 INSTR7 1039 293
1 S 250 INSTR7 1044 215
0 S 251 INSTR7 1046 247
0 S 252 INSTR7 1049 381
3 S 253 INSTR7 1052 271
2 S 254 INSTR7 1057 359
1 S 255 INSTR7 1062 302
1 S 256 INSTR7 1067 152
3 S 257 INSTR7 1069 143
2 S 258 INSTR7 1074 330
0 S 259 INSTR7 1078 241
0 S 260 INSTR7 1084 414
2 S 261 INSTR7 1086 117
3 S 262 INSTR7 1091 225
1 S 263 INSTR7 1095 262
3 S 264 INSTR7 1098 227
0 S 265 INSTR7 1100 217
2 S 266 INSTR7 1102 151
1 S 267 INSTR7 1105 86
2 S 268 INSTR7 1110 197
1 S 269 INSTR7 1113 157
3 S 270 INSTR7 1117 322
0 S 271 INSTR7 1121 109
1 S 272 INSTR7 1123 344
0 S 273 INSTR7 1126 298
3 S 274 INSTR7 1131 193
2 S 275 INSTR7 1137 111
2 S 276 INSTR7 1143 69
1 S 277 INSTR7 1147 338
3 S 278 INSTR7 1149 344
0 S 279 INSTR7 1151 365
1 S 280 INSTR7 1156 138
0 S 281 INSTR7 1158 142
3 S 282 INSTR7 1163 341
2 S 283 INSTR7 1168 252
3 S 284 INSTR7 1172 166
0 S 285 INSTR7 1177 75
2 S 286 INSTR7 1179 329
1 S 287 INSTR7 1184 299
0 S 288 INSTR7 1190 234
2 S 289 INSTR7 1193 324
3 S 290 INSTR7 1198 135
1 S 291 INSTR7 1201 106
0 S 292 INSTR7 1203 173
2 S 293 INSTR7 1207 122
1 S 294 INSTR7 1211 394
3 S 295 INSTR7 1217 302
1 S 296 INSTR7 1221 86
2 S 297 INSTR7 1224 404
0 S 298 INSTR7 1228 372
3 S 299 INSTR7 1231 232
2 S 300 INSTR7 1235 122
0 S 301 INSTR7 1241 353
1 S 302 INSTR7 1243 392
3 S 303 INSTR7 1247 75
2 S 304 INSTR7 1252 240
0 S 305 INSTR7 1258 365
1 S 306 INSTR7 1262 410
3 S 307 INSTR7 1266 275
3 S 308 INSTR7 1270 73
1 S 309 INSTR7 1272 349
2 S 310 INSTR7 1277 306
0 S 311 INSTR7 1280 321
3 S 312 INSTR7 1284 305
0 S 313 INSTR7 1289 135
2 S 314 INSTR7 1294 351
1 S 315 INSTR7 1298 314
3 S 316 INSTR7 1301 160
1 S 317 INSTR7 1306 332
0 S 318 INSTR7 1308 135
2 S 319 INSTR7 1310 93
3 S 320 INSTR7 1316 234
0 S 321 INSTR7 1318 79
2 S 322 INSTR7 1321 162
1 S 323 INSTR7 1326 213
2 S 324 INSTR7 1331 98
0 S 325 INSTR7 1334 394
1 S 326 INSTR7 1340 247
3 S 327 INSTR7 1342 209
1 S 328 INSTR7 1346 98
0 S 329 INSTR7 1348 344
2 S 330 INSTR7 1350 226
3 S 331 INSTR7 1354 303
0 S 332 INSTR7 1356 239
3 S 333 INSTR7 1361 279
2 S 334 INSTR7 1367 305
1 S 335 INSTR7 1373 112
3 S 336 INSTR7 1376 125
0 S 337 INSTR7 1380 345
1 S 338 INSTR7 1383 225
2 S 339 INSTR7 1385 159
1 S 340 INSTR7 1391 381
3 S 341 INSTR7 1394 147
2 S 342 INSTR7 1399 368
0 S 343 INSTR7 1404 377
0 S 344 INSTR7 1410 312
